{
 "cells": [
  {
   "cell_type": "code",
   "execution_count": 32,
   "metadata": {},
   "outputs": [
    {
     "name": "stdout",
     "output_type": "stream",
     "text": [
      "ERROR! Session/line number was not unique in database. History logging moved to new session 117\n"
     ]
    }
   ],
   "source": [
    "import pandas as pd\n",
    "import matplotlib.pyplot as plt\n",
    "import matplotlib as mpl\n",
    "import numpy as np"
   ]
  },
  {
   "cell_type": "code",
   "execution_count": 33,
   "metadata": {},
   "outputs": [],
   "source": [
    "import os\n",
    "os.getcwd()"
   ]
  },
  {
   "cell_type": "code",
   "execution_count": null,
   "metadata": {},
   "outputs": [
    {
     "name": "stderr",
     "output_type": "stream",
     "text": [
      "ERROR:root:Internal Python error in the inspect module.\n",
      "Below is the traceback from this internal error.\n",
      "\n",
      "ERROR:root:Internal Python error in the inspect module.\n",
      "Below is the traceback from this internal error.\n",
      "\n",
      "ERROR:root:Internal Python error in the inspect module.\n",
      "Below is the traceback from this internal error.\n",
      "\n"
     ]
    },
    {
     "name": "stdout",
     "output_type": "stream",
     "text": [
      "Traceback (most recent call last):\n",
      "  File \"/Users/siqisun/Downloads/anaconda3/lib/python3.8/site-packages/IPython/core/interactiveshell.py\", line 3418, in run_code\n",
      "    exec(code_obj, self.user_global_ns, self.user_ns)\n",
      "  File \"<ipython-input-32-858742ae9156>\", line 1, in <module>\n",
      "    summary = pd.read_csv(\"summary.csv\")\n",
      "  File \"/Users/siqisun/Downloads/anaconda3/lib/python3.8/site-packages/pandas/io/parsers.py\", line 686, in read_csv\n",
      "    return _read(filepath_or_buffer, kwds)\n",
      "  File \"/Users/siqisun/Downloads/anaconda3/lib/python3.8/site-packages/pandas/io/parsers.py\", line 452, in _read\n",
      "    parser = TextFileReader(fp_or_buf, **kwds)\n",
      "  File \"/Users/siqisun/Downloads/anaconda3/lib/python3.8/site-packages/pandas/io/parsers.py\", line 946, in __init__\n",
      "    self._make_engine(self.engine)\n",
      "  File \"/Users/siqisun/Downloads/anaconda3/lib/python3.8/site-packages/pandas/io/parsers.py\", line 1178, in _make_engine\n",
      "    self._engine = CParserWrapper(self.f, **self.options)\n",
      "  File \"/Users/siqisun/Downloads/anaconda3/lib/python3.8/site-packages/pandas/io/parsers.py\", line 2008, in __init__\n",
      "    self._reader = parsers.TextReader(src, **kwds)\n",
      "  File \"pandas/_libs/parsers.pyx\", line 382, in pandas._libs.parsers.TextReader.__cinit__\n",
      "  File \"pandas/_libs/parsers.pyx\", line 674, in pandas._libs.parsers.TextReader._setup_parser_source\n",
      "PermissionError: [Errno 1] Operation not permitted: 'summary.csv'\n",
      "\n",
      "During handling of the above exception, another exception occurred:\n",
      "\n",
      "Traceback (most recent call last):\n",
      "  File \"/Users/siqisun/Downloads/anaconda3/lib/python3.8/site-packages/IPython/core/interactiveshell.py\", line 2045, in showtraceback\n",
      "    stb = value._render_traceback_()\n",
      "AttributeError: 'PermissionError' object has no attribute '_render_traceback_'\n",
      "\n",
      "During handling of the above exception, another exception occurred:\n",
      "\n",
      "Traceback (most recent call last):\n",
      "  File \"/Users/siqisun/Downloads/anaconda3/lib/python3.8/site-packages/IPython/core/ultratb.py\", line 1170, in get_records\n",
      "    return _fixed_getinnerframes(etb, number_of_lines_of_context, tb_offset)\n",
      "  File \"/Users/siqisun/Downloads/anaconda3/lib/python3.8/site-packages/IPython/core/ultratb.py\", line 316, in wrapped\n",
      "    return f(*args, **kwargs)\n",
      "  File \"/Users/siqisun/Downloads/anaconda3/lib/python3.8/site-packages/IPython/core/ultratb.py\", line 350, in _fixed_getinnerframes\n",
      "    records = fix_frame_records_filenames(inspect.getinnerframes(etb, context))\n",
      "  File \"/Users/siqisun/Downloads/anaconda3/lib/python3.8/inspect.py\", line 1503, in getinnerframes\n",
      "    frameinfo = (tb.tb_frame,) + getframeinfo(tb, context)\n",
      "  File \"/Users/siqisun/Downloads/anaconda3/lib/python3.8/inspect.py\", line 1461, in getframeinfo\n",
      "    filename = getsourcefile(frame) or getfile(frame)\n",
      "  File \"/Users/siqisun/Downloads/anaconda3/lib/python3.8/inspect.py\", line 708, in getsourcefile\n",
      "    if getattr(getmodule(object, filename), '__loader__', None) is not None:\n",
      "  File \"/Users/siqisun/Downloads/anaconda3/lib/python3.8/inspect.py\", line 737, in getmodule\n",
      "    file = getabsfile(object, _filename)\n",
      "  File \"/Users/siqisun/Downloads/anaconda3/lib/python3.8/inspect.py\", line 721, in getabsfile\n",
      "    return os.path.normcase(os.path.abspath(_filename))\n",
      "  File \"/Users/siqisun/Downloads/anaconda3/lib/python3.8/posixpath.py\", line 379, in abspath\n",
      "    cwd = os.getcwd()\n",
      "PermissionError: [Errno 1] Operation not permitted\n",
      "Traceback (most recent call last):\n",
      "  File \"/Users/siqisun/Downloads/anaconda3/lib/python3.8/site-packages/IPython/core/interactiveshell.py\", line 3418, in run_code\n",
      "    exec(code_obj, self.user_global_ns, self.user_ns)\n",
      "  File \"<ipython-input-32-858742ae9156>\", line 1, in <module>\n",
      "    summary = pd.read_csv(\"summary.csv\")\n",
      "  File \"/Users/siqisun/Downloads/anaconda3/lib/python3.8/site-packages/pandas/io/parsers.py\", line 686, in read_csv\n",
      "    return _read(filepath_or_buffer, kwds)\n",
      "  File \"/Users/siqisun/Downloads/anaconda3/lib/python3.8/site-packages/pandas/io/parsers.py\", line 452, in _read\n",
      "    parser = TextFileReader(fp_or_buf, **kwds)\n",
      "  File \"/Users/siqisun/Downloads/anaconda3/lib/python3.8/site-packages/pandas/io/parsers.py\", line 946, in __init__\n",
      "    self._make_engine(self.engine)\n",
      "  File \"/Users/siqisun/Downloads/anaconda3/lib/python3.8/site-packages/pandas/io/parsers.py\", line 1178, in _make_engine\n",
      "    self._engine = CParserWrapper(self.f, **self.options)\n",
      "  File \"/Users/siqisun/Downloads/anaconda3/lib/python3.8/site-packages/pandas/io/parsers.py\", line 2008, in __init__\n",
      "    self._reader = parsers.TextReader(src, **kwds)\n",
      "  File \"pandas/_libs/parsers.pyx\", line 382, in pandas._libs.parsers.TextReader.__cinit__\n",
      "  File \"pandas/_libs/parsers.pyx\", line 674, in pandas._libs.parsers.TextReader._setup_parser_source\n",
      "PermissionError: [Errno 1] Operation not permitted: 'summary.csv'\n",
      "\n",
      "During handling of the above exception, another exception occurred:\n",
      "\n",
      "Traceback (most recent call last):\n",
      "  File \"/Users/siqisun/Downloads/anaconda3/lib/python3.8/site-packages/IPython/core/interactiveshell.py\", line 2045, in showtraceback\n",
      "    stb = value._render_traceback_()\n",
      "AttributeError: 'PermissionError' object has no attribute '_render_traceback_'\n",
      "\n",
      "During handling of the above exception, another exception occurred:\n",
      "\n",
      "Traceback (most recent call last):\n",
      "  File \"/Users/siqisun/Downloads/anaconda3/lib/python3.8/site-packages/IPython/core/interactiveshell.py\", line 3338, in run_ast_nodes\n",
      "    if (await self.run_code(code, result,  async_=asy)):\n",
      "  File \"/Users/siqisun/Downloads/anaconda3/lib/python3.8/site-packages/IPython/core/interactiveshell.py\", line 3435, in run_code\n",
      "    self.showtraceback(running_compiled_code=True)\n",
      "  File \"/Users/siqisun/Downloads/anaconda3/lib/python3.8/site-packages/IPython/core/interactiveshell.py\", line 2047, in showtraceback\n",
      "    stb = self.InteractiveTB.structured_traceback(etype,\n",
      "  File \"/Users/siqisun/Downloads/anaconda3/lib/python3.8/site-packages/IPython/core/ultratb.py\", line 1436, in structured_traceback\n",
      "    return FormattedTB.structured_traceback(\n",
      "  File \"/Users/siqisun/Downloads/anaconda3/lib/python3.8/site-packages/IPython/core/ultratb.py\", line 1336, in structured_traceback\n",
      "    return VerboseTB.structured_traceback(\n",
      "  File \"/Users/siqisun/Downloads/anaconda3/lib/python3.8/site-packages/IPython/core/ultratb.py\", line 1193, in structured_traceback\n",
      "    formatted_exception = self.format_exception_as_a_whole(etype, evalue, etb, number_of_lines_of_context,\n",
      "  File \"/Users/siqisun/Downloads/anaconda3/lib/python3.8/site-packages/IPython/core/ultratb.py\", line 1151, in format_exception_as_a_whole\n",
      "    last_unique, recursion_repeat = find_recursion(orig_etype, evalue, records)\n",
      "  File \"/Users/siqisun/Downloads/anaconda3/lib/python3.8/site-packages/IPython/core/ultratb.py\", line 451, in find_recursion\n",
      "    return len(records), 0\n",
      "TypeError: object of type 'NoneType' has no len()\n",
      "\n",
      "During handling of the above exception, another exception occurred:\n",
      "\n",
      "Traceback (most recent call last):\n",
      "  File \"/Users/siqisun/Downloads/anaconda3/lib/python3.8/site-packages/IPython/core/interactiveshell.py\", line 2045, in showtraceback\n",
      "    stb = value._render_traceback_()\n",
      "AttributeError: 'TypeError' object has no attribute '_render_traceback_'\n",
      "\n",
      "During handling of the above exception, another exception occurred:\n",
      "\n",
      "Traceback (most recent call last):\n",
      "  File \"/Users/siqisun/Downloads/anaconda3/lib/python3.8/site-packages/IPython/core/ultratb.py\", line 1170, in get_records\n",
      "    return _fixed_getinnerframes(etb, number_of_lines_of_context, tb_offset)\n",
      "  File \"/Users/siqisun/Downloads/anaconda3/lib/python3.8/site-packages/IPython/core/ultratb.py\", line 316, in wrapped\n",
      "    return f(*args, **kwargs)\n",
      "  File \"/Users/siqisun/Downloads/anaconda3/lib/python3.8/site-packages/IPython/core/ultratb.py\", line 350, in _fixed_getinnerframes\n",
      "    records = fix_frame_records_filenames(inspect.getinnerframes(etb, context))\n",
      "  File \"/Users/siqisun/Downloads/anaconda3/lib/python3.8/inspect.py\", line 1503, in getinnerframes\n",
      "    frameinfo = (tb.tb_frame,) + getframeinfo(tb, context)\n",
      "  File \"/Users/siqisun/Downloads/anaconda3/lib/python3.8/inspect.py\", line 1461, in getframeinfo\n",
      "    filename = getsourcefile(frame) or getfile(frame)\n",
      "  File \"/Users/siqisun/Downloads/anaconda3/lib/python3.8/inspect.py\", line 708, in getsourcefile\n",
      "    if getattr(getmodule(object, filename), '__loader__', None) is not None:\n",
      "  File \"/Users/siqisun/Downloads/anaconda3/lib/python3.8/inspect.py\", line 737, in getmodule\n",
      "    file = getabsfile(object, _filename)\n",
      "  File \"/Users/siqisun/Downloads/anaconda3/lib/python3.8/inspect.py\", line 721, in getabsfile\n",
      "    return os.path.normcase(os.path.abspath(_filename))\n",
      "  File \"/Users/siqisun/Downloads/anaconda3/lib/python3.8/posixpath.py\", line 379, in abspath\n",
      "    cwd = os.getcwd()\n",
      "PermissionError: [Errno 1] Operation not permitted\n",
      "Traceback (most recent call last):\n",
      "  File \"/Users/siqisun/Downloads/anaconda3/lib/python3.8/site-packages/IPython/core/interactiveshell.py\", line 3418, in run_code\n",
      "    exec(code_obj, self.user_global_ns, self.user_ns)\n",
      "  File \"<ipython-input-32-858742ae9156>\", line 1, in <module>\n",
      "    summary = pd.read_csv(\"summary.csv\")\n",
      "  File \"/Users/siqisun/Downloads/anaconda3/lib/python3.8/site-packages/pandas/io/parsers.py\", line 686, in read_csv\n",
      "    return _read(filepath_or_buffer, kwds)\n",
      "  File \"/Users/siqisun/Downloads/anaconda3/lib/python3.8/site-packages/pandas/io/parsers.py\", line 452, in _read\n",
      "    parser = TextFileReader(fp_or_buf, **kwds)\n",
      "  File \"/Users/siqisun/Downloads/anaconda3/lib/python3.8/site-packages/pandas/io/parsers.py\", line 946, in __init__\n",
      "    self._make_engine(self.engine)\n",
      "  File \"/Users/siqisun/Downloads/anaconda3/lib/python3.8/site-packages/pandas/io/parsers.py\", line 1178, in _make_engine\n",
      "    self._engine = CParserWrapper(self.f, **self.options)\n",
      "  File \"/Users/siqisun/Downloads/anaconda3/lib/python3.8/site-packages/pandas/io/parsers.py\", line 2008, in __init__\n",
      "    self._reader = parsers.TextReader(src, **kwds)\n",
      "  File \"pandas/_libs/parsers.pyx\", line 382, in pandas._libs.parsers.TextReader.__cinit__\n",
      "  File \"pandas/_libs/parsers.pyx\", line 674, in pandas._libs.parsers.TextReader._setup_parser_source\n",
      "PermissionError: [Errno 1] Operation not permitted: 'summary.csv'\n",
      "\n",
      "During handling of the above exception, another exception occurred:\n",
      "\n",
      "Traceback (most recent call last):\n",
      "  File \"/Users/siqisun/Downloads/anaconda3/lib/python3.8/site-packages/IPython/core/interactiveshell.py\", line 2045, in showtraceback\n",
      "    stb = value._render_traceback_()\n",
      "AttributeError: 'PermissionError' object has no attribute '_render_traceback_'\n",
      "\n",
      "During handling of the above exception, another exception occurred:\n",
      "\n",
      "Traceback (most recent call last):\n",
      "  File \"/Users/siqisun/Downloads/anaconda3/lib/python3.8/site-packages/IPython/core/interactiveshell.py\", line 3338, in run_ast_nodes\n",
      "    if (await self.run_code(code, result,  async_=asy)):\n",
      "  File \"/Users/siqisun/Downloads/anaconda3/lib/python3.8/site-packages/IPython/core/interactiveshell.py\", line 3435, in run_code\n",
      "    self.showtraceback(running_compiled_code=True)\n",
      "  File \"/Users/siqisun/Downloads/anaconda3/lib/python3.8/site-packages/IPython/core/interactiveshell.py\", line 2047, in showtraceback\n",
      "    stb = self.InteractiveTB.structured_traceback(etype,\n",
      "  File \"/Users/siqisun/Downloads/anaconda3/lib/python3.8/site-packages/IPython/core/ultratb.py\", line 1436, in structured_traceback\n",
      "    return FormattedTB.structured_traceback(\n",
      "  File \"/Users/siqisun/Downloads/anaconda3/lib/python3.8/site-packages/IPython/core/ultratb.py\", line 1336, in structured_traceback\n",
      "    return VerboseTB.structured_traceback(\n",
      "  File \"/Users/siqisun/Downloads/anaconda3/lib/python3.8/site-packages/IPython/core/ultratb.py\", line 1193, in structured_traceback\n",
      "    formatted_exception = self.format_exception_as_a_whole(etype, evalue, etb, number_of_lines_of_context,\n",
      "  File \"/Users/siqisun/Downloads/anaconda3/lib/python3.8/site-packages/IPython/core/ultratb.py\", line 1151, in format_exception_as_a_whole\n",
      "    last_unique, recursion_repeat = find_recursion(orig_etype, evalue, records)\n",
      "  File \"/Users/siqisun/Downloads/anaconda3/lib/python3.8/site-packages/IPython/core/ultratb.py\", line 451, in find_recursion\n",
      "    return len(records), 0\n",
      "TypeError: object of type 'NoneType' has no len()\n",
      "\n",
      "During handling of the above exception, another exception occurred:\n",
      "\n",
      "Traceback (most recent call last):\n",
      "  File \"/Users/siqisun/Downloads/anaconda3/lib/python3.8/site-packages/IPython/core/interactiveshell.py\", line 2045, in showtraceback\n",
      "    stb = value._render_traceback_()\n",
      "AttributeError: 'TypeError' object has no attribute '_render_traceback_'\n",
      "\n",
      "During handling of the above exception, another exception occurred:\n",
      "\n",
      "Traceback (most recent call last):\n",
      "  File \"/Users/siqisun/Downloads/anaconda3/lib/python3.8/site-packages/IPython/core/interactiveshell.py\", line 2923, in _run_cell\n",
      "    return runner(coro)\n",
      "  File \"/Users/siqisun/Downloads/anaconda3/lib/python3.8/site-packages/IPython/core/async_helpers.py\", line 68, in _pseudo_sync_runner\n",
      "    coro.send(None)\n",
      "  File \"/Users/siqisun/Downloads/anaconda3/lib/python3.8/site-packages/IPython/core/interactiveshell.py\", line 3146, in run_cell_async\n",
      "    has_raised = await self.run_ast_nodes(code_ast.body, cell_name,\n",
      "  File \"/Users/siqisun/Downloads/anaconda3/lib/python3.8/site-packages/IPython/core/interactiveshell.py\", line 3357, in run_ast_nodes\n",
      "    self.showtraceback()\n",
      "  File \"/Users/siqisun/Downloads/anaconda3/lib/python3.8/site-packages/IPython/core/interactiveshell.py\", line 2047, in showtraceback\n",
      "    stb = self.InteractiveTB.structured_traceback(etype,\n",
      "  File \"/Users/siqisun/Downloads/anaconda3/lib/python3.8/site-packages/IPython/core/ultratb.py\", line 1436, in structured_traceback\n",
      "    return FormattedTB.structured_traceback(\n",
      "  File \"/Users/siqisun/Downloads/anaconda3/lib/python3.8/site-packages/IPython/core/ultratb.py\", line 1336, in structured_traceback\n",
      "    return VerboseTB.structured_traceback(\n",
      "  File \"/Users/siqisun/Downloads/anaconda3/lib/python3.8/site-packages/IPython/core/ultratb.py\", line 1211, in structured_traceback\n",
      "    formatted_exceptions += self.format_exception_as_a_whole(etype, evalue, etb, lines_of_context,\n",
      "  File \"/Users/siqisun/Downloads/anaconda3/lib/python3.8/site-packages/IPython/core/ultratb.py\", line 1151, in format_exception_as_a_whole\n",
      "    last_unique, recursion_repeat = find_recursion(orig_etype, evalue, records)\n",
      "  File \"/Users/siqisun/Downloads/anaconda3/lib/python3.8/site-packages/IPython/core/ultratb.py\", line 451, in find_recursion\n",
      "    return len(records), 0\n",
      "TypeError: object of type 'NoneType' has no len()\n",
      "\n",
      "During handling of the above exception, another exception occurred:\n",
      "\n",
      "Traceback (most recent call last):\n",
      "  File \"/Users/siqisun/Downloads/anaconda3/lib/python3.8/site-packages/IPython/core/interactiveshell.py\", line 2045, in showtraceback\n",
      "    stb = value._render_traceback_()\n",
      "AttributeError: 'TypeError' object has no attribute '_render_traceback_'\n",
      "\n",
      "During handling of the above exception, another exception occurred:\n",
      "\n",
      "Traceback (most recent call last):\n",
      "  File \"/Users/siqisun/Downloads/anaconda3/lib/python3.8/site-packages/IPython/core/ultratb.py\", line 1170, in get_records\n",
      "    return _fixed_getinnerframes(etb, number_of_lines_of_context, tb_offset)\n",
      "  File \"/Users/siqisun/Downloads/anaconda3/lib/python3.8/site-packages/IPython/core/ultratb.py\", line 316, in wrapped\n",
      "    return f(*args, **kwargs)\n",
      "  File \"/Users/siqisun/Downloads/anaconda3/lib/python3.8/site-packages/IPython/core/ultratb.py\", line 350, in _fixed_getinnerframes\n",
      "    records = fix_frame_records_filenames(inspect.getinnerframes(etb, context))\n",
      "  File \"/Users/siqisun/Downloads/anaconda3/lib/python3.8/inspect.py\", line 1503, in getinnerframes\n",
      "    frameinfo = (tb.tb_frame,) + getframeinfo(tb, context)\n",
      "  File \"/Users/siqisun/Downloads/anaconda3/lib/python3.8/inspect.py\", line 1461, in getframeinfo\n",
      "    filename = getsourcefile(frame) or getfile(frame)\n",
      "  File \"/Users/siqisun/Downloads/anaconda3/lib/python3.8/inspect.py\", line 708, in getsourcefile\n",
      "    if getattr(getmodule(object, filename), '__loader__', None) is not None:\n",
      "  File \"/Users/siqisun/Downloads/anaconda3/lib/python3.8/inspect.py\", line 737, in getmodule\n",
      "    file = getabsfile(object, _filename)\n",
      "  File \"/Users/siqisun/Downloads/anaconda3/lib/python3.8/inspect.py\", line 721, in getabsfile\n",
      "    return os.path.normcase(os.path.abspath(_filename))\n",
      "  File \"/Users/siqisun/Downloads/anaconda3/lib/python3.8/posixpath.py\", line 379, in abspath\n",
      "    cwd = os.getcwd()\n",
      "PermissionError: [Errno 1] Operation not permitted\n"
     ]
    }
   ],
   "source": [
    "summary = pd.read_csv(\"summary.csv\")\n",
    "summary.head()"
   ]
  },
  {
   "cell_type": "code",
   "execution_count": 24,
   "metadata": {},
   "outputs": [
    {
     "name": "stderr",
     "output_type": "stream",
     "text": [
      "<ipython-input-24-d13f29aa9a0a>:2: SettingWithCopyWarning: \n",
      "A value is trying to be set on a copy of a slice from a DataFrame.\n",
      "Try using .loc[row_indexer,col_indexer] = value instead\n",
      "\n",
      "See the caveats in the documentation: https://pandas.pydata.org/pandas-docs/stable/user_guide/indexing.html#returning-a-view-versus-a-copy\n",
      "  pa_time[\"date_val\"] = pd.to_datetime(pa_time[\"date_val\"])\n"
     ]
    },
    {
     "data": {
      "text/html": [
       "<div>\n",
       "<style scoped>\n",
       "    .dataframe tbody tr th:only-of-type {\n",
       "        vertical-align: middle;\n",
       "    }\n",
       "\n",
       "    .dataframe tbody tr th {\n",
       "        vertical-align: top;\n",
       "    }\n",
       "\n",
       "    .dataframe thead th {\n",
       "        text-align: right;\n",
       "    }\n",
       "</style>\n",
       "<table border=\"1\" class=\"dataframe\">\n",
       "  <thead>\n",
       "    <tr style=\"text-align: right;\">\n",
       "      <th></th>\n",
       "      <th>pharmacy_claim_approved</th>\n",
       "      <th>date_val</th>\n",
       "      <th>calendar_year</th>\n",
       "      <th>calendar_month</th>\n",
       "    </tr>\n",
       "    <tr>\n",
       "      <th>date_val</th>\n",
       "      <th></th>\n",
       "      <th></th>\n",
       "      <th></th>\n",
       "      <th></th>\n",
       "    </tr>\n",
       "  </thead>\n",
       "  <tbody>\n",
       "    <tr>\n",
       "      <th>2017-01-01</th>\n",
       "      <td>0</td>\n",
       "      <td>2017-01-01</td>\n",
       "      <td>2017</td>\n",
       "      <td>1</td>\n",
       "    </tr>\n",
       "    <tr>\n",
       "      <th>2017-01-01</th>\n",
       "      <td>1</td>\n",
       "      <td>2017-01-01</td>\n",
       "      <td>2017</td>\n",
       "      <td>1</td>\n",
       "    </tr>\n",
       "    <tr>\n",
       "      <th>2017-01-01</th>\n",
       "      <td>0</td>\n",
       "      <td>2017-01-01</td>\n",
       "      <td>2017</td>\n",
       "      <td>1</td>\n",
       "    </tr>\n",
       "    <tr>\n",
       "      <th>2017-01-01</th>\n",
       "      <td>1</td>\n",
       "      <td>2017-01-01</td>\n",
       "      <td>2017</td>\n",
       "      <td>1</td>\n",
       "    </tr>\n",
       "    <tr>\n",
       "      <th>2017-01-01</th>\n",
       "      <td>1</td>\n",
       "      <td>2017-01-01</td>\n",
       "      <td>2017</td>\n",
       "      <td>1</td>\n",
       "    </tr>\n",
       "  </tbody>\n",
       "</table>\n",
       "</div>"
      ],
      "text/plain": [
       "            pharmacy_claim_approved   date_val  calendar_year  calendar_month\n",
       "date_val                                                                     \n",
       "2017-01-01                        0 2017-01-01           2017               1\n",
       "2017-01-01                        1 2017-01-01           2017               1\n",
       "2017-01-01                        0 2017-01-01           2017               1\n",
       "2017-01-01                        1 2017-01-01           2017               1\n",
       "2017-01-01                        1 2017-01-01           2017               1"
      ]
     },
     "execution_count": 24,
     "metadata": {},
     "output_type": "execute_result"
    }
   ],
   "source": [
    "pa_time = summary[[\"pharmacy_claim_approved\", \"date_val\", \"calendar_year\", \"calendar_month\"]]\n",
    "pa_time[\"date_val\"] = pd.to_datetime(pa_time[\"date_val\"]) \n",
    "pa_time.index = pa_time[\"date_val\"]\n",
    "pa_time.head()"
   ]
  },
  {
   "cell_type": "code",
   "execution_count": 30,
   "metadata": {},
   "outputs": [
    {
     "data": {
      "text/plain": [
       "2019    494999\n",
       "2018    455917\n",
       "2017    384660\n",
       "Name: calendar_year, dtype: int64"
      ]
     },
     "execution_count": 30,
     "metadata": {},
     "output_type": "execute_result"
    }
   ],
   "source": [
    "pa_time[\"calendar_year\"].value_counts()"
   ]
  },
  {
   "cell_type": "code",
   "execution_count": null,
   "metadata": {},
   "outputs": [
    {
     "name": "stderr",
     "output_type": "stream",
     "text": [
      "ERROR:root:Internal Python error in the inspect module.\n",
      "Below is the traceback from this internal error.\n",
      "\n",
      "ERROR:root:Internal Python error in the inspect module.\n",
      "Below is the traceback from this internal error.\n",
      "\n",
      "ERROR:root:Internal Python error in the inspect module.\n",
      "Below is the traceback from this internal error.\n",
      "\n"
     ]
    },
    {
     "name": "stdout",
     "output_type": "stream",
     "text": [
      "Traceback (most recent call last):\n",
      "  File \"/Users/siqisun/Downloads/anaconda3/lib/python3.8/site-packages/IPython/core/interactiveshell.py\", line 3418, in run_code\n",
      "    exec(code_obj, self.user_global_ns, self.user_ns)\n",
      "  File \"<ipython-input-31-55b17c250dd3>\", line 10, in <module>\n",
      "    approval_rate_2019 = date_PA_approved(dim_date_claim_pa, 2019)\n",
      "NameError: name 'dim_date_claim_pa' is not defined\n",
      "\n",
      "During handling of the above exception, another exception occurred:\n",
      "\n",
      "Traceback (most recent call last):\n",
      "  File \"/Users/siqisun/Downloads/anaconda3/lib/python3.8/site-packages/IPython/core/interactiveshell.py\", line 2045, in showtraceback\n",
      "    stb = value._render_traceback_()\n",
      "AttributeError: 'NameError' object has no attribute '_render_traceback_'\n",
      "\n",
      "During handling of the above exception, another exception occurred:\n",
      "\n",
      "Traceback (most recent call last):\n",
      "  File \"/Users/siqisun/Downloads/anaconda3/lib/python3.8/site-packages/IPython/core/ultratb.py\", line 1170, in get_records\n",
      "    return _fixed_getinnerframes(etb, number_of_lines_of_context, tb_offset)\n",
      "  File \"/Users/siqisun/Downloads/anaconda3/lib/python3.8/site-packages/IPython/core/ultratb.py\", line 316, in wrapped\n",
      "    return f(*args, **kwargs)\n",
      "  File \"/Users/siqisun/Downloads/anaconda3/lib/python3.8/site-packages/IPython/core/ultratb.py\", line 350, in _fixed_getinnerframes\n",
      "    records = fix_frame_records_filenames(inspect.getinnerframes(etb, context))\n",
      "  File \"/Users/siqisun/Downloads/anaconda3/lib/python3.8/inspect.py\", line 1503, in getinnerframes\n",
      "    frameinfo = (tb.tb_frame,) + getframeinfo(tb, context)\n",
      "  File \"/Users/siqisun/Downloads/anaconda3/lib/python3.8/inspect.py\", line 1461, in getframeinfo\n",
      "    filename = getsourcefile(frame) or getfile(frame)\n",
      "  File \"/Users/siqisun/Downloads/anaconda3/lib/python3.8/inspect.py\", line 708, in getsourcefile\n",
      "    if getattr(getmodule(object, filename), '__loader__', None) is not None:\n",
      "  File \"/Users/siqisun/Downloads/anaconda3/lib/python3.8/inspect.py\", line 737, in getmodule\n",
      "    file = getabsfile(object, _filename)\n",
      "  File \"/Users/siqisun/Downloads/anaconda3/lib/python3.8/inspect.py\", line 721, in getabsfile\n",
      "    return os.path.normcase(os.path.abspath(_filename))\n",
      "  File \"/Users/siqisun/Downloads/anaconda3/lib/python3.8/posixpath.py\", line 379, in abspath\n",
      "    cwd = os.getcwd()\n",
      "PermissionError: [Errno 1] Operation not permitted\n",
      "Traceback (most recent call last):\n",
      "  File \"/Users/siqisun/Downloads/anaconda3/lib/python3.8/site-packages/IPython/core/interactiveshell.py\", line 3418, in run_code\n",
      "    exec(code_obj, self.user_global_ns, self.user_ns)\n",
      "  File \"<ipython-input-31-55b17c250dd3>\", line 10, in <module>\n",
      "    approval_rate_2019 = date_PA_approved(dim_date_claim_pa, 2019)\n",
      "NameError: name 'dim_date_claim_pa' is not defined\n",
      "\n",
      "During handling of the above exception, another exception occurred:\n",
      "\n",
      "Traceback (most recent call last):\n",
      "  File \"/Users/siqisun/Downloads/anaconda3/lib/python3.8/site-packages/IPython/core/interactiveshell.py\", line 2045, in showtraceback\n",
      "    stb = value._render_traceback_()\n",
      "AttributeError: 'NameError' object has no attribute '_render_traceback_'\n",
      "\n",
      "During handling of the above exception, another exception occurred:\n",
      "\n",
      "Traceback (most recent call last):\n",
      "  File \"/Users/siqisun/Downloads/anaconda3/lib/python3.8/site-packages/IPython/core/interactiveshell.py\", line 3338, in run_ast_nodes\n",
      "    if (await self.run_code(code, result,  async_=asy)):\n",
      "  File \"/Users/siqisun/Downloads/anaconda3/lib/python3.8/site-packages/IPython/core/interactiveshell.py\", line 3435, in run_code\n",
      "    self.showtraceback(running_compiled_code=True)\n",
      "  File \"/Users/siqisun/Downloads/anaconda3/lib/python3.8/site-packages/IPython/core/interactiveshell.py\", line 2047, in showtraceback\n",
      "    stb = self.InteractiveTB.structured_traceback(etype,\n",
      "  File \"/Users/siqisun/Downloads/anaconda3/lib/python3.8/site-packages/IPython/core/ultratb.py\", line 1436, in structured_traceback\n",
      "    return FormattedTB.structured_traceback(\n",
      "  File \"/Users/siqisun/Downloads/anaconda3/lib/python3.8/site-packages/IPython/core/ultratb.py\", line 1336, in structured_traceback\n",
      "    return VerboseTB.structured_traceback(\n",
      "  File \"/Users/siqisun/Downloads/anaconda3/lib/python3.8/site-packages/IPython/core/ultratb.py\", line 1193, in structured_traceback\n",
      "    formatted_exception = self.format_exception_as_a_whole(etype, evalue, etb, number_of_lines_of_context,\n",
      "  File \"/Users/siqisun/Downloads/anaconda3/lib/python3.8/site-packages/IPython/core/ultratb.py\", line 1151, in format_exception_as_a_whole\n",
      "    last_unique, recursion_repeat = find_recursion(orig_etype, evalue, records)\n",
      "  File \"/Users/siqisun/Downloads/anaconda3/lib/python3.8/site-packages/IPython/core/ultratb.py\", line 451, in find_recursion\n",
      "    return len(records), 0\n",
      "TypeError: object of type 'NoneType' has no len()\n",
      "\n",
      "During handling of the above exception, another exception occurred:\n",
      "\n",
      "Traceback (most recent call last):\n",
      "  File \"/Users/siqisun/Downloads/anaconda3/lib/python3.8/site-packages/IPython/core/interactiveshell.py\", line 2045, in showtraceback\n",
      "    stb = value._render_traceback_()\n",
      "AttributeError: 'TypeError' object has no attribute '_render_traceback_'\n",
      "\n",
      "During handling of the above exception, another exception occurred:\n",
      "\n",
      "Traceback (most recent call last):\n",
      "  File \"/Users/siqisun/Downloads/anaconda3/lib/python3.8/site-packages/IPython/core/ultratb.py\", line 1170, in get_records\n",
      "    return _fixed_getinnerframes(etb, number_of_lines_of_context, tb_offset)\n",
      "  File \"/Users/siqisun/Downloads/anaconda3/lib/python3.8/site-packages/IPython/core/ultratb.py\", line 316, in wrapped\n",
      "    return f(*args, **kwargs)\n",
      "  File \"/Users/siqisun/Downloads/anaconda3/lib/python3.8/site-packages/IPython/core/ultratb.py\", line 350, in _fixed_getinnerframes\n",
      "    records = fix_frame_records_filenames(inspect.getinnerframes(etb, context))\n",
      "  File \"/Users/siqisun/Downloads/anaconda3/lib/python3.8/inspect.py\", line 1503, in getinnerframes\n",
      "    frameinfo = (tb.tb_frame,) + getframeinfo(tb, context)\n",
      "  File \"/Users/siqisun/Downloads/anaconda3/lib/python3.8/inspect.py\", line 1461, in getframeinfo\n",
      "    filename = getsourcefile(frame) or getfile(frame)\n",
      "  File \"/Users/siqisun/Downloads/anaconda3/lib/python3.8/inspect.py\", line 708, in getsourcefile\n",
      "    if getattr(getmodule(object, filename), '__loader__', None) is not None:\n",
      "  File \"/Users/siqisun/Downloads/anaconda3/lib/python3.8/inspect.py\", line 737, in getmodule\n",
      "    file = getabsfile(object, _filename)\n",
      "  File \"/Users/siqisun/Downloads/anaconda3/lib/python3.8/inspect.py\", line 721, in getabsfile\n",
      "    return os.path.normcase(os.path.abspath(_filename))\n",
      "  File \"/Users/siqisun/Downloads/anaconda3/lib/python3.8/posixpath.py\", line 379, in abspath\n",
      "    cwd = os.getcwd()\n",
      "PermissionError: [Errno 1] Operation not permitted\n",
      "Traceback (most recent call last):\n",
      "  File \"/Users/siqisun/Downloads/anaconda3/lib/python3.8/site-packages/IPython/core/interactiveshell.py\", line 3418, in run_code\n",
      "    exec(code_obj, self.user_global_ns, self.user_ns)\n",
      "  File \"<ipython-input-31-55b17c250dd3>\", line 10, in <module>\n",
      "    approval_rate_2019 = date_PA_approved(dim_date_claim_pa, 2019)\n",
      "NameError: name 'dim_date_claim_pa' is not defined\n",
      "\n",
      "During handling of the above exception, another exception occurred:\n",
      "\n",
      "Traceback (most recent call last):\n",
      "  File \"/Users/siqisun/Downloads/anaconda3/lib/python3.8/site-packages/IPython/core/interactiveshell.py\", line 2045, in showtraceback\n",
      "    stb = value._render_traceback_()\n",
      "AttributeError: 'NameError' object has no attribute '_render_traceback_'\n",
      "\n",
      "During handling of the above exception, another exception occurred:\n",
      "\n",
      "Traceback (most recent call last):\n",
      "  File \"/Users/siqisun/Downloads/anaconda3/lib/python3.8/site-packages/IPython/core/interactiveshell.py\", line 3338, in run_ast_nodes\n",
      "    if (await self.run_code(code, result,  async_=asy)):\n",
      "  File \"/Users/siqisun/Downloads/anaconda3/lib/python3.8/site-packages/IPython/core/interactiveshell.py\", line 3435, in run_code\n",
      "    self.showtraceback(running_compiled_code=True)\n",
      "  File \"/Users/siqisun/Downloads/anaconda3/lib/python3.8/site-packages/IPython/core/interactiveshell.py\", line 2047, in showtraceback\n",
      "    stb = self.InteractiveTB.structured_traceback(etype,\n",
      "  File \"/Users/siqisun/Downloads/anaconda3/lib/python3.8/site-packages/IPython/core/ultratb.py\", line 1436, in structured_traceback\n",
      "    return FormattedTB.structured_traceback(\n",
      "  File \"/Users/siqisun/Downloads/anaconda3/lib/python3.8/site-packages/IPython/core/ultratb.py\", line 1336, in structured_traceback\n",
      "    return VerboseTB.structured_traceback(\n",
      "  File \"/Users/siqisun/Downloads/anaconda3/lib/python3.8/site-packages/IPython/core/ultratb.py\", line 1193, in structured_traceback\n",
      "    formatted_exception = self.format_exception_as_a_whole(etype, evalue, etb, number_of_lines_of_context,\n",
      "  File \"/Users/siqisun/Downloads/anaconda3/lib/python3.8/site-packages/IPython/core/ultratb.py\", line 1151, in format_exception_as_a_whole\n",
      "    last_unique, recursion_repeat = find_recursion(orig_etype, evalue, records)\n",
      "  File \"/Users/siqisun/Downloads/anaconda3/lib/python3.8/site-packages/IPython/core/ultratb.py\", line 451, in find_recursion\n",
      "    return len(records), 0\n",
      "TypeError: object of type 'NoneType' has no len()\n",
      "\n",
      "During handling of the above exception, another exception occurred:\n",
      "\n",
      "Traceback (most recent call last):\n",
      "  File \"/Users/siqisun/Downloads/anaconda3/lib/python3.8/site-packages/IPython/core/interactiveshell.py\", line 2045, in showtraceback\n",
      "    stb = value._render_traceback_()\n",
      "AttributeError: 'TypeError' object has no attribute '_render_traceback_'\n",
      "\n",
      "During handling of the above exception, another exception occurred:\n",
      "\n",
      "Traceback (most recent call last):\n",
      "  File \"/Users/siqisun/Downloads/anaconda3/lib/python3.8/site-packages/IPython/core/interactiveshell.py\", line 2923, in _run_cell\n",
      "    return runner(coro)\n",
      "  File \"/Users/siqisun/Downloads/anaconda3/lib/python3.8/site-packages/IPython/core/async_helpers.py\", line 68, in _pseudo_sync_runner\n",
      "    coro.send(None)\n",
      "  File \"/Users/siqisun/Downloads/anaconda3/lib/python3.8/site-packages/IPython/core/interactiveshell.py\", line 3146, in run_cell_async\n",
      "    has_raised = await self.run_ast_nodes(code_ast.body, cell_name,\n",
      "  File \"/Users/siqisun/Downloads/anaconda3/lib/python3.8/site-packages/IPython/core/interactiveshell.py\", line 3357, in run_ast_nodes\n",
      "    self.showtraceback()\n",
      "  File \"/Users/siqisun/Downloads/anaconda3/lib/python3.8/site-packages/IPython/core/interactiveshell.py\", line 2047, in showtraceback\n",
      "    stb = self.InteractiveTB.structured_traceback(etype,\n",
      "  File \"/Users/siqisun/Downloads/anaconda3/lib/python3.8/site-packages/IPython/core/ultratb.py\", line 1436, in structured_traceback\n",
      "    return FormattedTB.structured_traceback(\n",
      "  File \"/Users/siqisun/Downloads/anaconda3/lib/python3.8/site-packages/IPython/core/ultratb.py\", line 1336, in structured_traceback\n",
      "    return VerboseTB.structured_traceback(\n",
      "  File \"/Users/siqisun/Downloads/anaconda3/lib/python3.8/site-packages/IPython/core/ultratb.py\", line 1211, in structured_traceback\n",
      "    formatted_exceptions += self.format_exception_as_a_whole(etype, evalue, etb, lines_of_context,\n",
      "  File \"/Users/siqisun/Downloads/anaconda3/lib/python3.8/site-packages/IPython/core/ultratb.py\", line 1151, in format_exception_as_a_whole\n",
      "    last_unique, recursion_repeat = find_recursion(orig_etype, evalue, records)\n",
      "  File \"/Users/siqisun/Downloads/anaconda3/lib/python3.8/site-packages/IPython/core/ultratb.py\", line 451, in find_recursion\n",
      "    return len(records), 0\n",
      "TypeError: object of type 'NoneType' has no len()\n",
      "\n",
      "During handling of the above exception, another exception occurred:\n",
      "\n",
      "Traceback (most recent call last):\n",
      "  File \"/Users/siqisun/Downloads/anaconda3/lib/python3.8/site-packages/IPython/core/interactiveshell.py\", line 2045, in showtraceback\n",
      "    stb = value._render_traceback_()\n",
      "AttributeError: 'TypeError' object has no attribute '_render_traceback_'\n",
      "\n",
      "During handling of the above exception, another exception occurred:\n",
      "\n",
      "Traceback (most recent call last):\n",
      "  File \"/Users/siqisun/Downloads/anaconda3/lib/python3.8/site-packages/IPython/core/ultratb.py\", line 1170, in get_records\n",
      "    return _fixed_getinnerframes(etb, number_of_lines_of_context, tb_offset)\n",
      "  File \"/Users/siqisun/Downloads/anaconda3/lib/python3.8/site-packages/IPython/core/ultratb.py\", line 316, in wrapped\n",
      "    return f(*args, **kwargs)\n",
      "  File \"/Users/siqisun/Downloads/anaconda3/lib/python3.8/site-packages/IPython/core/ultratb.py\", line 350, in _fixed_getinnerframes\n",
      "    records = fix_frame_records_filenames(inspect.getinnerframes(etb, context))\n",
      "  File \"/Users/siqisun/Downloads/anaconda3/lib/python3.8/inspect.py\", line 1503, in getinnerframes\n",
      "    frameinfo = (tb.tb_frame,) + getframeinfo(tb, context)\n",
      "  File \"/Users/siqisun/Downloads/anaconda3/lib/python3.8/inspect.py\", line 1461, in getframeinfo\n",
      "    filename = getsourcefile(frame) or getfile(frame)\n",
      "  File \"/Users/siqisun/Downloads/anaconda3/lib/python3.8/inspect.py\", line 708, in getsourcefile\n",
      "    if getattr(getmodule(object, filename), '__loader__', None) is not None:\n",
      "  File \"/Users/siqisun/Downloads/anaconda3/lib/python3.8/inspect.py\", line 737, in getmodule\n",
      "    file = getabsfile(object, _filename)\n",
      "  File \"/Users/siqisun/Downloads/anaconda3/lib/python3.8/inspect.py\", line 721, in getabsfile\n",
      "    return os.path.normcase(os.path.abspath(_filename))\n",
      "  File \"/Users/siqisun/Downloads/anaconda3/lib/python3.8/posixpath.py\", line 379, in abspath\n",
      "    cwd = os.getcwd()\n",
      "PermissionError: [Errno 1] Operation not permitted\n"
     ]
    }
   ],
   "source": [
    "def date_PA_approved(df, year):\n",
    "    PA_approval_rates = []\n",
    "    for i in range(1, 13):\n",
    "        PA_requests = len(df[(df['calendar_month']==i) &(df['calendar_year']==year)])\n",
    "        PA_approved = len(df[(df['calendar_month']==i)&(df['pharmacy_claim_approved']==1)&(df['calendar_year']==year)])\n",
    "        \n",
    "        PA_approval_rate = (PA_approved/PA_requests)*100\n",
    "        PA_approval_rates.append(PA_approval_rate)\n",
    "    return PA_approval_rates\n",
    "approval_rate_2019 = date_PA_approved(dim_date_claim_pa, 2019)\n",
    "approval_rate_2018 = date_PA_approved(dim_date_claim_pa, 2018)\n",
    "approval_rate_2017 = date_PA_approved(dim_date_claim_pa, 2017)"
   ]
  },
  {
   "cell_type": "code",
   "execution_count": 26,
   "metadata": {},
   "outputs": [],
   "source": [
    "        pa_approve = sum(records)\n",
    "        pa_time[\"pa_rate\"]\n",
    "years = pa_time[\"calendar_year\"].unique()"
   ]
  },
  {
   "cell_type": "code",
   "execution_count": null,
   "metadata": {},
   "outputs": [],
   "source": [
    "# Draw Plot\n",
    "plt.figure(figsize=(16,12), dpi= 80)\n",
    "for i, y in enumerate(years):\n",
    "    if i > 0:        \n",
    "        plt.plot('month', 'value', data=pa_time.loc[pa_time.year==y, :], color=mycolors[i], label=y)\n",
    "        plt.text(pa_time.loc[pa_time.year==y, :].shape[0]-.9, pa_time.loc[pa_time.year==y, 'value'][-1:].values[0], y, fontsize=12, color=mycolors[i])\n"
   ]
  },
  {
   "cell_type": "code",
   "execution_count": null,
   "metadata": {},
   "outputs": [],
   "source": []
  }
 ],
 "metadata": {
  "kernelspec": {
   "display_name": "Python 3",
   "language": "python",
   "name": "python3"
  },
  "language_info": {
   "codemirror_mode": {
    "name": "ipython",
    "version": 3
   },
   "file_extension": ".py",
   "mimetype": "text/x-python",
   "name": "python",
   "nbconvert_exporter": "python",
   "pygments_lexer": "ipython3",
   "version": "3.8.5"
  }
 },
 "nbformat": 4,
 "nbformat_minor": 4
}
